<!--
 * @Author: OCEAN.GZY
 * @Date: 2022-08-11 23:07:50
 * @LastEditors: OCEAN.GZY
 * @LastEditTime: 2022-08-11 23:11:07
 * @FilePath: \ocean-books\C++实战100天\chap3\3_13.md
 * @Description: 注释信息
-->
# 异常处理

### 异常介绍
异常是程序在执行期间产生的问题，C++ 异常是指在程序运行时发生的特殊情况(如被零除情况或内存不足警告)。异常提供了一种转移程序控制权的方式。C++ 异常处理涉及到三个关键字：try、catch、throw。

- try: try 块中的代码标识将被激活的特定异常。它后面通常跟着一个或多个 catch 块。
- catch: 在您想要处理问题的地方，通过异常处理程序捕获异常。catch 关键字用于捕获异常。
- throw: 当问题出现时，程序会抛出一个异常。这是通过使用 throw 关键字来完成的。

举一个例子，将下面的代码写入 /home/shiyanlou/Code/exception.cpp 文件中：
```
#include <iostream>

using namespace std;

int division(int a,int b)
{
    if(b == 0)
        throw "除数不能为0";        //抛出异常
    return a/b;
}

int main()
{
    int a,b;
    cout<<"输入被除数和除数:"<<endl;
    cin>>a>>b;
    try// 保护代码
    {
        cout<<"a / b = "<<division(a,b);
    }
    catch(const char* msg)        // 能处理任何异常的代码
    {
        cerr<<msg<<endl;
    }
    return 0;
}
```

### 语法
从上面的例子中我们不难看出异常操作的语法。

抛出异常:
```
throw  Exception
```
捕获异常:
```
try
{
       // 保护代码
}catch(...)
{
      // 能处理任何异常的代码
}
```

### 常处理进阶
##### 堆栈解退
当抛出了异常，但还没在特定的作用域中被捕获时，函数调用堆栈便被“解退”，并试图在下一个外层 try...catch 代码中捕获这个异常。解退函数调用堆栈意味着抛出未捕获异常的那个函数将终止，这个函数中的所有局部变量都将销毁，控制会返回到原先调用这个函数的语句。

实例, 将下面的代码写入 /home/shiyanlou/Code/test.cpp 文件中：
```
#include <iostream>

using namespace std;

void fun3()
{
    cout<<"In fun 3"<<endl;
    throw"runtime_error in fun3";        //抛出异常,fun1,fun2终止
}

void fun2()
{
    cout<<"fun3 is called inside fun2"<<endl;
    fun3();                                //调用fun3()
}

void fun1()
{
    cout<<"fun2 is called inside fun1"<<endl;
    fun2();                                //调用fun2()
}

int main()
{
    try
    {
        cout<<"fun1 is called inside main"<<endl;
        fun1();
    }
    catch(const char* msg)                //捕获异常
    {
        cout<<"exception occurred: "<< msg<<endl;
        cout<<"exception handled in main"<<endl;
    }

    return 0;
}
```
- 迷失

异常什么时候会迷失方向呢？

- 意外异常：如果是在带异常规范的函数中引发的，则必须与规范列表里的某个异常匹配，若没有匹配的，则为意外异常，默认情况下，会导致程序异常终止
- 未捕获异常：如果不是在函数中引发的（或者函数没有异常规范），则它必须被捕获。如果没被捕获（没有 try 块或没有匹配的 catch 块），则为未捕获异常。默认情况下，将导致程序异常终止

```
#include <iostream>
#include <exception>
#include <stdexcept>
using namespace std;

int main()
{
    int c;
    logic_error a("logic_error");                //定义一个逻辑异常
    range_error b("runtime_error");                //定义一个作用域异常
    try
    {
        cout<<"输入一个数:";
        cin>>c;
        switch(c)
        {
            case 1:
                throw a;
                break;
            default:
                cout << "throw a runtime_error" << endl;//抛出一个作用域异常
                throw b;
                break;
        }
    }
    catch(const logic_error & e)
    {
        cout << e.what() << endl;
    }
    catch(...)                                    //捕获其它所有可能的异常，程序终止
    {
        cout << "OK" << endl;
        terminate();
    }

    return 0;
}
```

- 局限性

全局对象在程序开始运行前进行构造，如果构造函数抛出异常，将永远无法捕获，析构也是如此，因为它们在程序结束后才会被调用，这些异常只有操作系统才可以捕获，应用程序没有办法。 对于局部对象，异常处理机制是所有从 try 到 throw 语句之间构造起来的局部对象的析构函数将被自动调用，然后清退栈堆（就像 main 函数退出那样），如果一直回溯到 main 函数后还是没有匹配到 catch 块，那么系统会调用 terminate() 终止整个程序，在这种情况下就不能保证局部对象会被正确的销毁了。

### 实现自己的异常处理
想要实现自己的异常处理函数库，需要派生基类 exception，然后自己定义虚函数 what()。

将下面的代码写入 /home/shiyanlou/Code/test2.cpp 文件中：
```
#include <iostream>
#include <exception>

using namespace std;

class myexception : public exception        //自定义一个异常类
{
public:
    myexception(){}
    const char* what()
    {
        return "There has an exception";
    }

};

int division(int a,int b)
{
    if(b == 0)
        throw myexception();                //抛出异常
    return a/b;
}

int main()
{
    int a,b;
    cout<<"输入被除数和除数:"<<endl;
    cin>>a>>b;
    try// 保护代码
    {
        cout<<"a / b = "<<division(a,b);
    }
    catch(myexception &e)                    // 捕获异常
    {
        cout<< e.what()<<endl;
    }


    return 0;
}
```